Traceback (most recent call last):
  File "classification\train.py", line 66, in <module>
    train(args.config)
  File "classification\train.py", line 48, in train
    model.fit(
  File "D:\Program\Anaconda3\envs\tf2\lib\site-packages\keras\engine\training.py", line 1230, in fit
    callbacks.on_epoch_end(epoch, epoch_logs)
  File "D:\Program\Anaconda3\envs\tf2\lib\site-packages\keras\callbacks.py", line 413, in on_epoch_end
    callback.on_epoch_end(epoch, logs)
  File "D:\Program\Anaconda3\envs\tf2\lib\site-packages\keras\callbacks.py", line 1039, in on_epoch_end
    self._finalize_progbar(logs, self._train_step)
  File "D:\Program\Anaconda3\envs\tf2\lib\site-packages\keras\callbacks.py", line 1112, in _finalize_progbar
    self.progbar.update(self.target, list(logs.items()), finalize=True)
  File "D:\Program\Anaconda3\envs\tf2\lib\site-packages\keras\utils\generic_utils.py", line 973, in update
    sys.stdout.flush()
  File "D:\Program\Anaconda3\envs\tf2\lib\socket.py", line 687, in write
    return self._sock.send(b)
ConnectionAbortedError: [WinError 10053] 你的主机中的软件中止了一个已建立的连接。
Exception ignored in: <_io.TextIOWrapper name=1688 mode='w' encoding='cp936'>
Traceback (most recent call last):
  File "D:\Program\Anaconda3\envs\tf2\lib\socket.py", line 687, in write
    return self._sock.send(b)
ConnectionAbortedError: [WinError 10053] 你的主机中的软件中止了一个已建立的连接。
